<h1><center>异常处理</center></h1>

# error

## 1. error接口

错误是指程序种出现不正常的情况，从而导致程序无法正常运行。比如尝试打开一个文件，文件系统中不存在这个文件。这是一个异常情况，表现为一个错误。

Go语言通过内置的`错误类型`提供了非常简单的错误处理机制。即error接口。接口的定义如下：

```go
type error interface{
    Error() string
}
```

**error本质上是一个接口类型**，其中包含了`Error()`方法，错误值可以存储在变量中，通过函数返回。

```go
// 计算平方根
func Sqrt(f float64) (float64, error) {
	if f < 0 {
		return 0, errors.New("negative inputs")
	} else {
		return math.Sqrt(f), nil
	}
}

// 除法运算函数
func Divide(a float64, b float64) (float64, error) {
	if b == 0 {
		return 0, errors.New("error: divided by zero")
	} else {
		return a / b, nil
	}
}

func main() {
	// 异常情况1
	res := math.Sqrt(-100)
	fmt.Printf("%T\t%+v\n", res, res) // float64 NaN
	res, err := Sqrt(-100)
	if err != nil {
		fmt.Println(err) // negative inputs
	} else {
		fmt.Println(res)
	}
	// 异常情况2
	res, err = Divide(100, 0)
	if err != nil {
		fmt.Println(err) // error: divided by zero
	} else {
		fmt.Println(res)
	}
}
```

## 2. 创建error对象

结构体只要实现了`Error() string` 这种刚发，就代表实现了该错误接口，返回值为错误的具体描述。

通常程序会发生可预知的错误，所以Go语言`errors`包提供了用户自定义的方法，errors包下的`New()`函数返回新创建的error对象。

errors包内代码如下：

```go
// package errors implements functions to manipulate errors.
package errors
// New returns an error that formats as the given text.
func New(text string) error{
    return &errorString{text}
}
// errorString is a trivial implementation of error.
type errorString struct{
    s string
}
func (e *errorString) Error() string{
    return e.s
}
```

Go语言的`errors.go`源码定义了一个结构体，名为`errorString`，它实现了Error()方法，实现了error接口。

`errors`包向外暴露了一个`New()`函数，该函数参数为字符串，返回值为error类型

`fmt`包下的`Errorf()`函数返回`error`对象，它本质上还是调用`errors.New()`，使用格式如下：

```go
// Errorf formats according to a format specifier and returns the string
// as a value that satisfies error.
func Errorf(format string, a ... interface{}) error{
    return errors.New(Sprintf(format, a...))
}
```

> 实例演练

创建error对象

```go
func checkAge(age int) (string, error) {
	if age < 0 {
		return "", fmt.Errorf("age(%d) is negative", age)
	} else {
		return fmt.Sprintf("age is %d", age), nil
	}
}

func main() {
	// 1. 方式一
	err1 := errors.New("自己创建的错误!")
	fmt.Println(err1.Error())           // 自己创建的错误!
	fmt.Println(err1)                   // 自己创建的错误!
	fmt.Printf("type(err1):%T\n", err1) // *errors.errorString
	// 2. 方式二
	err2 := fmt.Errorf("错误的类型%d", 10)
	fmt.Println(err2.Error())           // 错误的类型10
	fmt.Println(err2)                   // 错误的类型10
	fmt.Printf("type(err2):%T\n", err2) // *errors.errorString
	// 3. 方式三
	res, err := checkAge(-12)
	if err != nil {
		fmt.Println(err.Error()) // age(-12) is negative
		fmt.Println(err) // age(-12) is negative
	} else {
		fmt.Println(res)
	}
}
```

## 3. 自定义错误

自定义错误的实现步骤如下：

1. 定义一个结构体，表示自定义错误的类型
2. 让自定义错误类型实现error接口，Error() string
3. 定义一个返回error的函数，根据程序实际功能而定

```go
// 1. 定义结构体
type MyError struct {
	When time.Time
	What string
}

// 2. 实现Error() 方法
func (e MyError) Error() string {
	return fmt.Sprintf("[%v] : %v", e.When, e.What)
}

// 3. 定义函数，返回error对昂
func getArea(width, height float64) (float64, error) {
	errorInfo := ""
	if width < 0 && height < 0 {
		errorInfo = fmt.Sprintf("width: %.2f, height: %.2f is negative", width, height)
	} else if width < 0 {
		errorInfo = fmt.Sprintf("width: %.2f is negative", width)
	} else if height < 0 {
		errorInfo = fmt.Sprintf("width: %.2f is negative", height)
	}
	if errorInfo != "" {
		return 0, MyError{time.Now(), errorInfo}
	} else {
		return width * height, nil
	}
}

func main() {
	res, err := getArea(-4, -5)
	if err != nil {
		fmt.Printf(err.Error())
		// [2022-10-02 22:29:40.1299492 +0800 CST m=+0.004585401] : width: -4.00, height: -5.00 is negative
	} else {
		fmt.Printf("Area is %.2f", res)
	}
}
```

# defer

关键字`defer`用于延迟一个函数或方法(或者当前所创建的匿名函数)的执行。

`defer`语句智能出现在函数或方法内部。

## 1. 函数使用

在函数中可以添加多个`defer`语句。如果有很多调用`defer`，当函数执行到最后时，这些`defer`语句会按照逆序执行(报错的时候也会执行)，最后该函数返回

```go
func funcA() {
	fmt.Println("This is funcA()")
}

func funcB() {
	fmt.Println("This is funcB()")
}

func funcC() {
	fmt.Println("This is funcC()")
}

func main() {
	defer funcA()
	funcB()
	defer funcC()
	fmt.Println("main over...")
	//This is funcB()
	//main over...   
	//This is funcC()
	//This is funcA()
}
```

`defer`语句经常被用于处理成对的操作，如 打开-关闭，连接-断开连接，加锁-释放锁。

特别是在执行打开资源的操作时，遇到错误需要提前返回，在返回前需要关闭相应的资源，不然很容易造成资源泄露等问题。

```go
func finished() {
	fmt.Println("结束!")
}

func getLargest(s []int) {
	defer finished()
	fmt.Println("Begin find the largest value")
	max := s[0]
	for _, value := range s {
		if value > max {
			max = value
		}
	}
	fmt.Printf("The max value is %d\n", max)
}
func main() {
	s1 := []int{100, 78, 2, 400, 324}
	getLargest(s1)
	//Begin find the largest value
	//The max value is 400
	//结束! 
}
```

## 2. 方法使用

延迟也同样适用于方法。

```go
type Person struct {
	firstName, lastName string
}

func (p Person) fullName() {
	fmt.Printf("%s %s", p.firstName, p.lastName)
}
func main() {
	p := Person{"Steven", "Wang"}
	defer p.fullName()
	fmt.Println("Welcome")
	//Welcome
	//Steven Wang
}
```

## 3. defer参数

延迟函数的参数在执行延迟语句时被执行，而不是在执行实际的函数调用时执行。

```go
func printAdd(a, b int, flag bool) {
	if flag {
		fmt.Printf("延迟执行函数printAdd(), 参数 a, b 分别为%d %d, 两数之和为：%d\n", a, b, a+b)
	} else {
		fmt.Printf("未延迟执行函数printAdd(), 参数 a, b 分别为%d %d, 两数之和为：%d\n", a, b, a+b)
	}
}

func main() {
	a := 5
	b := 6
	defer printAdd(a, b, true) // 此时参数a, b已经传递过来，只是没有立即执行
	a = 10
	b = 7
	printAdd(a, b, false)
	//未延迟执行函数printAdd(), 参数 a, b 分别为10 7, 两数之和为：17
	//延迟执行函数printAdd(), 参数 a, b 分别为5 6, 两数之和为：11
}
```

## 4. 堆栈的推迟

当一个函数有多个延迟调用时，它们被添加到一个堆栈中，并按照先进后出的顺序执行

```go
func main() {
	str := "Hello World"
	fmt.Println(str)
	// Hello World
	fmt.Println("反转后的字符串")
	ReverseString(str)
	// dlroW olleH
}
func ReverseString(text string) {
	for _, ch := range text {
		defer fmt.Printf("%c", ch)
	}
}
```

---

# panic & recover

> panic

Go语言追求简洁优雅,Go没有像Java那样`try...cache...finnally`异常处理机制

Go的设计者认为，将异常与流程控制混在一起会让代码变得混乱。

<center><strong>panic, 中断程序的执行</strong></center>

`panic()`是一个内建函数，可以中断原有的控制流程。

```go
func TestA() {
	fmt.Println("func TestA()")
}
func TestB() {
	// panic
	panic("panic func TestB()")
}
func TestC() {
	fmt.Println("func TestC()")
}

func main() {
	TestA()
	TestB() //  TestB()发生异常，中断程序
	TestC()
    // func TestA()
	// panic: func TestB(): panic
}
```

> recover

recover()可以让进入panic()的流程恢复过来，并获取流程控制权。

recover()让程序恢复，必须在延迟函数defer中执行。recover()仅在延迟函数中有效

在正常的程序运行过程中，调用recover()会返回nil,并且没有任何效果。

如果当前的流程进入panic状态，调用recover()可以捕获panic()的输入值，使得程序恢复正常运行。

```go
func funcA() {
	fmt.Println("This is funcA()")
}
func funcB() {
	defer func() {
		if msg := recover(); msg != nil {
			fmt.Println("recover, get return values:", msg)
		}
	}() // function call
	fmt.Println("This is funcB()")
	for i := 0; i < 10; i++ {
		fmt.Println("i:", i)
		if i == 5 {
			panic("funcB() get panic")
		}
	}
}

func funcC() {
	defer func() {
		fmt.Println("execute defer func")
		msg := recover()
		fmt.Println("get recover value : ", msg)
	}()
	fmt.Println("This is funcC()")
	panic("funcC() get panic")
}

func main() {
	funcA()
	funcB()
	funcC()
	fmt.Println("main over")
}
```

:warning: 代码中应该尽量减少panic的使用
